Traceback (most recent call last):
  File "/home/ali/anaconda3/envs/new_torch/lib/python3.9/site-packages/jupyter_cache/executors/utils.py", line 51, in single_nb_execution
    executenb(
  File "/home/ali/anaconda3/envs/new_torch/lib/python3.9/site-packages/nbclient/client.py", line 1263, in execute
    return NotebookClient(nb=nb, resources=resources, km=km, **kwargs).execute()
  File "/home/ali/anaconda3/envs/new_torch/lib/python3.9/site-packages/nbclient/util.py", line 85, in wrapped
    return just_run(coro(*args, **kwargs))
  File "/home/ali/anaconda3/envs/new_torch/lib/python3.9/site-packages/nbclient/util.py", line 60, in just_run
    return loop.run_until_complete(coro)
  File "/home/ali/anaconda3/envs/new_torch/lib/python3.9/asyncio/base_events.py", line 647, in run_until_complete
    return future.result()
  File "/home/ali/anaconda3/envs/new_torch/lib/python3.9/site-packages/nbclient/client.py", line 701, in async_execute
    await self.async_execute_cell(
  File "/home/ali/anaconda3/envs/new_torch/lib/python3.9/site-packages/nbclient/client.py", line 1019, in async_execute_cell
    await self._check_raise_for_error(cell, cell_index, exec_reply)
  File "/home/ali/anaconda3/envs/new_torch/lib/python3.9/site-packages/nbclient/client.py", line 913, in _check_raise_for_error
    raise CellExecutionError.from_cell_and_msg(cell, exec_reply_content)
nbclient.exceptions.CellExecutionError: An error occurred while executing the following cell:
------------------
show_jupyter_image('OCT_7/AUTOREGRESSIVE_RESULTS_OCT7.png',width = 800, height = 200)
------------------

[0;31m---------------------------------------------------------------------------[0m
[0;31mNameError[0m                                 Traceback (most recent call last)
Cell [0;32mIn [6], line 1[0m
[0;32m----> 1[0m [43mshow_jupyter_image[49m[43m([49m[38;5;124;43m'[39;49m[38;5;124;43mOCT_7/AUTOREGRESSIVE_RESULTS_OCT7.png[39;49m[38;5;124;43m'[39;49m[43m,[49m[43mwidth[49m[43m [49m[38;5;241;43m=[39;49m[43m [49m[38;5;241;43m800[39;49m[43m,[49m[43m [49m[43mheight[49m[43m [49m[38;5;241;43m=[39;49m[43m [49m[38;5;241;43m200[39;49m[43m)[49m

Cell [0;32mIn [5], line 3[0m, in [0;36mshow_jupyter_image[0;34m(image_filename, width, height)[0m
[1;32m      1[0m [38;5;28;01mdef[39;00m [38;5;21mshow_jupyter_image[39m(image_filename, width [38;5;241m=[39m [38;5;241m1300[39m, height [38;5;241m=[39m [38;5;241m300[39m):
[1;32m      2[0m     [38;5;124;03m"""Show a saved image directly in jupyter. Make sure image_filename is in your IQN_BASE !"""[39;00m
[0;32m----> 3[0m     display(Image(os[38;5;241m.[39mpath[38;5;241m.[39mjoin([43mIQN_BASE[49m,image_filename), width [38;5;241m=[39m width, height [38;5;241m=[39m height  ))

[0;31mNameError[0m: name 'IQN_BASE' is not defined
NameError: name 'IQN_BASE' is not defined

